2019-01-03 19:39:55,520 ERROR: Exception on /favicon.ico [GET] [in /home/gene/Desktop/DESKTOP/DESKTOP/groupfrontend/venv/lib/python3.6/site-packages/flask/app.py:1761]
Traceback (most recent call last):
  File "/home/gene/Desktop/DESKTOP/DESKTOP/groupfrontend/venv/lib/python3.6/site-packages/flask/app.py", line 1813, in full_dispatch_request
    rv = self.dispatch_request()
  File "/home/gene/Desktop/DESKTOP/DESKTOP/groupfrontend/venv/lib/python3.6/site-packages/flask/app.py", line 1791, in dispatch_request
    self.raise_routing_exception(req)
  File "/home/gene/Desktop/DESKTOP/DESKTOP/groupfrontend/venv/lib/python3.6/site-packages/flask/app.py", line 1774, in raise_routing_exception
    raise request.routing_exception
  File "/home/gene/Desktop/DESKTOP/DESKTOP/groupfrontend/venv/lib/python3.6/site-packages/flask/ctx.py", line 336, in match_request
    self.url_adapter.match(return_rule=True)
  File "/home/gene/Desktop/DESKTOP/DESKTOP/groupfrontend/venv/lib/python3.6/site-packages/werkzeug/routing.py", line 1581, in match
    raise NotFound()
werkzeug.exceptions.NotFound: 404 Not Found: The requested URL was not found on the server.  If you entered the URL manually please check your spelling and try again.

During handling of the above exception, another exception occurred:

Traceback (most recent call last):
  File "/home/gene/Desktop/DESKTOP/DESKTOP/groupfrontend/venv/lib/python3.6/site-packages/flask/app.py", line 2292, in wsgi_app
    response = self.full_dispatch_request()
  File "/home/gene/Desktop/DESKTOP/DESKTOP/groupfrontend/venv/lib/python3.6/site-packages/flask/app.py", line 1815, in full_dispatch_request
    rv = self.handle_user_exception(e)
  File "/home/gene/Desktop/DESKTOP/DESKTOP/groupfrontend/venv/lib/python3.6/site-packages/flask/app.py", line 1713, in handle_user_exception
    return self.handle_http_exception(e)
  File "/home/gene/Desktop/DESKTOP/DESKTOP/groupfrontend/venv/lib/python3.6/site-packages/flask/app.py", line 1644, in handle_http_exception
    return handler(e)
  File "/home/gene/Desktop/DESKTOP/DESKTOP/groupfrontend/app/errors.py", line 6, in not_found_error
    return render_template('404.html'), 404
  File "/home/gene/Desktop/DESKTOP/DESKTOP/groupfrontend/venv/lib/python3.6/site-packages/flask/templating.py", line 135, in render_template
    context, ctx.app)
  File "/home/gene/Desktop/DESKTOP/DESKTOP/groupfrontend/venv/lib/python3.6/site-packages/flask/templating.py", line 117, in _render
    rv = template.render(context)
  File "/home/gene/Desktop/DESKTOP/DESKTOP/groupfrontend/venv/lib/python3.6/site-packages/jinja2/asyncsupport.py", line 76, in render
    return original_render(self, *args, **kwargs)
  File "/home/gene/Desktop/DESKTOP/DESKTOP/groupfrontend/venv/lib/python3.6/site-packages/jinja2/environment.py", line 1008, in render
    return self.environment.handle_exception(exc_info, True)
  File "/home/gene/Desktop/DESKTOP/DESKTOP/groupfrontend/venv/lib/python3.6/site-packages/jinja2/environment.py", line 780, in handle_exception
    reraise(exc_type, exc_value, tb)
  File "/home/gene/Desktop/DESKTOP/DESKTOP/groupfrontend/venv/lib/python3.6/site-packages/jinja2/_compat.py", line 37, in reraise
    raise value.with_traceback(tb)
  File "/home/gene/Desktop/DESKTOP/DESKTOP/groupfrontend/app/templates/base.html", line 16, in template
    <a href="{{ url_for{'user', username=current_user.username) }}">Profile</a>
  File "/home/gene/Desktop/DESKTOP/DESKTOP/groupfrontend/venv/lib/python3.6/site-packages/jinja2/environment.py", line 1005, in render
    return concat(self.root_render_func(self.new_context(vars)))
  File "/home/gene/Desktop/DESKTOP/DESKTOP/groupfrontend/app/templates/404.html", line 1, in top-level template code
    {% extends "base.html" %}
  File "/home/gene/Desktop/DESKTOP/DESKTOP/groupfrontend/venv/lib/python3.6/site-packages/jinja2/environment.py", line 780, in handle_exception
    reraise(exc_type, exc_value, tb)
  File "/home/gene/Desktop/DESKTOP/DESKTOP/groupfrontend/venv/lib/python3.6/site-packages/jinja2/_compat.py", line 37, in reraise
    raise value.with_traceback(tb)
  File "/home/gene/Desktop/DESKTOP/DESKTOP/groupfrontend/app/templates/base.html", line 16, in template
    <a href="{{ url_for{'user', username=current_user.username) }}">Profile</a>
  File "/home/gene/Desktop/DESKTOP/DESKTOP/groupfrontend/venv/lib/python3.6/site-packages/jinja2/environment.py", line 497, in _parse
    return Parser(self, source, name, encode_filename(filename)).parse()
  File "/home/gene/Desktop/DESKTOP/DESKTOP/groupfrontend/venv/lib/python3.6/site-packages/jinja2/parser.py", line 901, in parse
    result = nodes.Template(self.subparse(), lineno=1)
  File "/home/gene/Desktop/DESKTOP/DESKTOP/groupfrontend/venv/lib/python3.6/site-packages/jinja2/parser.py", line 883, in subparse
    rv = self.parse_statement()
  File "/home/gene/Desktop/DESKTOP/DESKTOP/groupfrontend/venv/lib/python3.6/site-packages/jinja2/parser.py", line 130, in parse_statement
    return getattr(self, 'parse_' + self.stream.current.value)()
  File "/home/gene/Desktop/DESKTOP/DESKTOP/groupfrontend/venv/lib/python3.6/site-packages/jinja2/parser.py", line 223, in parse_if
    drop_needle=True)
  File "/home/gene/Desktop/DESKTOP/DESKTOP/groupfrontend/venv/lib/python3.6/site-packages/jinja2/parser.py", line 165, in parse_statements
    result = self.subparse(end_tokens)
  File "/home/gene/Desktop/DESKTOP/DESKTOP/groupfrontend/venv/lib/python3.6/site-packages/jinja2/parser.py", line 876, in subparse
    self.stream.expect('variable_end')
  File "/home/gene/Desktop/DESKTOP/DESKTOP/groupfrontend/venv/lib/python3.6/site-packages/jinja2/lexer.py", line 384, in expect
    self.name, self.filename)
jinja2.exceptions.TemplateSyntaxError: expected token 'end of print statement', got '{'
2019-01-03 19:40:23,370 INFO: Microblog startup [in /home/gene/Desktop/DESKTOP/DESKTOP/groupfrontend/app/__init__.py:47]
2019-01-03 19:41:11,527 ERROR: Exception on /reset_password_request [POST] [in /home/gene/Desktop/DESKTOP/DESKTOP/groupfrontend/venv/lib/python3.6/site-packages/flask/app.py:1761]
Traceback (most recent call last):
  File "/home/gene/Desktop/DESKTOP/DESKTOP/groupfrontend/venv/lib/python3.6/site-packages/flask/app.py", line 2292, in wsgi_app
    response = self.full_dispatch_request()
  File "/home/gene/Desktop/DESKTOP/DESKTOP/groupfrontend/venv/lib/python3.6/site-packages/flask/app.py", line 1815, in full_dispatch_request
    rv = self.handle_user_exception(e)
  File "/home/gene/Desktop/DESKTOP/DESKTOP/groupfrontend/venv/lib/python3.6/site-packages/flask/app.py", line 1718, in handle_user_exception
    reraise(exc_type, exc_value, tb)
  File "/home/gene/Desktop/DESKTOP/DESKTOP/groupfrontend/venv/lib/python3.6/site-packages/flask/_compat.py", line 35, in reraise
    raise value
  File "/home/gene/Desktop/DESKTOP/DESKTOP/groupfrontend/venv/lib/python3.6/site-packages/flask/app.py", line 1813, in full_dispatch_request
    rv = self.dispatch_request()
  File "/home/gene/Desktop/DESKTOP/DESKTOP/groupfrontend/venv/lib/python3.6/site-packages/flask/app.py", line 1799, in dispatch_request
    return self.view_functions[rule.endpoint](**req.view_args)
  File "/home/gene/Desktop/DESKTOP/DESKTOP/groupfrontend/app/routes.py", line 78, in reset_password_request
    send_password_reset_email(user)
NameError: name 'send_password_reset_email' is not defined
2019-01-03 19:42:27,496 INFO: Microblog startup [in /home/gene/Desktop/DESKTOP/DESKTOP/groupfrontend/app/__init__.py:47]
2019-01-03 19:42:36,494 ERROR: Exception on /reset_password_request [POST] [in /home/gene/Desktop/DESKTOP/DESKTOP/groupfrontend/venv/lib/python3.6/site-packages/flask/app.py:1761]
Traceback (most recent call last):
  File "/home/gene/Desktop/DESKTOP/DESKTOP/groupfrontend/venv/lib/python3.6/site-packages/flask/app.py", line 2292, in wsgi_app
    response = self.full_dispatch_request()
  File "/home/gene/Desktop/DESKTOP/DESKTOP/groupfrontend/venv/lib/python3.6/site-packages/flask/app.py", line 1815, in full_dispatch_request
    rv = self.handle_user_exception(e)
  File "/home/gene/Desktop/DESKTOP/DESKTOP/groupfrontend/venv/lib/python3.6/site-packages/flask/app.py", line 1718, in handle_user_exception
    reraise(exc_type, exc_value, tb)
  File "/home/gene/Desktop/DESKTOP/DESKTOP/groupfrontend/venv/lib/python3.6/site-packages/flask/_compat.py", line 35, in reraise
    raise value
  File "/home/gene/Desktop/DESKTOP/DESKTOP/groupfrontend/venv/lib/python3.6/site-packages/flask/app.py", line 1813, in full_dispatch_request
    rv = self.dispatch_request()
  File "/home/gene/Desktop/DESKTOP/DESKTOP/groupfrontend/venv/lib/python3.6/site-packages/flask/app.py", line 1799, in dispatch_request
    return self.view_functions[rule.endpoint](**req.view_args)
  File "/home/gene/Desktop/DESKTOP/DESKTOP/groupfrontend/app/routes.py", line 79, in reset_password_request
    send_password_reset_email(user)
  File "/home/gene/Desktop/DESKTOP/DESKTOP/groupfrontend/app/email.py", line 13, in send_password_reset_email
    token = user.get_reset_password_token()
  File "/home/gene/Desktop/DESKTOP/DESKTOP/groupfrontend/app/models.py", line 24, in get_reset_password_token
    return jwt.encode(
NameError: name 'jwt' is not defined
2019-01-03 19:43:22,918 INFO: Microblog startup [in /home/gene/Desktop/DESKTOP/DESKTOP/groupfrontend/app/__init__.py:47]
2019-01-03 19:45:23,709 INFO: Microblog startup [in /home/gene/Desktop/DESKTOP/DESKTOP/groupfrontend/app/__init__.py:47]
2019-01-03 20:02:06,630 INFO: Microblog startup [in /home/gene/Desktop/DESKTOP/DESKTOP/groupfrontend/app/__init__.py:49]
